Workbook

Sheet Instructions
A1: NTC Thermistor Calibration Template — How to Use
A3: Purpose
A4: Fit two models to each thermistor: the 2-parameter B model (R₀, B) and the 3-parameter Steinhart-Hart model (A, B, C). Plot of ln(R) vs 1/T should be a straight line with slope B. The Steinhart-Hart fit captures the mild curvature the B-model can't.
A6: Procedure — thermal setup
A7: 1. Fill a small insulated water bath (a vacuum flask or stirred beaker on a hotplate works). Bond the two thermistors together with your reference probe (multimeter temp probe or DS18B20) using a small blob of thermal compound wrapped in thin heat-shrink or PTFE tape. Goal: identical thermal mass touching the same water. 2. Stir continuously — unstirred water can have several-°C gradients between the probe and the thermistor only centimetres away. A small aquarium pump or magnetic stirrer is perfect. 3. Start cold (ice slurry, not just cold tap water — crushed ice + water gives a rock-solid 0.0 °C plateau for ~10 minutes). Then work upward: 10, 20, 30, 40, 50, 60, 70, 80 °C. You can drop points if you're short on time — eight good points is plenty. 4. At each set-point, wait until BOTH the reference reading and the thermistor resistance stop drifting (usually 60–120 s after you stop adding heat or ice). Record T_ref and R_meas simultaneously into the Thermistor_1 / Thermistor_2 sheets.
A9: Procedure — electrical
A10: • Measure R in 2-wire mode on your multimeter if R is above ~1 kΩ; use 4-wire if it's lower. • Keep your DMM's test current low (most meters apply <1 mA on the kΩ range); glass-bead NTCs have dissipation constants around 1–2 mW/°C in still water, much better when submerged and stirred. At 1 mA through a 10 kΩ bead, P = 10 mW, which gives a few mK of self-heating in stirred water — fine. In still air you'd get several °C of error. • Leave the same wiring between bench and bath throughout calibration. Contact resistance changes are your enemy.
A12: What the columns do
A13: T_ref (°C) and R_meas (Ω) are your inputs (blue cells). Everything else auto-computes: T in Kelvin, 1/T, ln(R), the fitted resistance from the B-model, and the residual %. The (ln R)³ helper columns feed the LINEST call that solves the Steinhart-Hart coefficients.
A15: Reading the fit
A16: • B value: typical glass-bead NTCs are 3000–4500 K. A value outside that range usually means either the part is unusual or your data has a bad point. • R²: you want ≥ 0.999 for a clean bead. Lower than 0.995 means you've got non-equilibrium points or a bad contact. • Residual (%): should be within ±1 % across most of the range for the B-model; the Steinhart-Hart fit typically brings this down to <0.1 % if your data is clean.
A18: Google Sheets notes
A19: This file opens directly in Google Sheets (File → Import → Upload). All formulas (SLOPE, INTERCEPT, RSQ, LINEST, INDEX, IFERROR, EXP, LN) work identically there. The embedded scatter chart may render as a static object; if you want to edit it, right-click → 'Open with Google Sheets' or recreate: Insert → Chart → Scatter → X = column E (1/T), Y = column F (ln R).

Sheet Analysis Notes
A1: Analysis Notes — v2 additions
A3: What changed
A4: Added a new analysis block at the bottom of each thermistor sheet (rows 45–66) and six new helper columns (L–Q). The original 20-point full-range B-model and Steinhart-Hart fits are untouched, so you can compare the two approaches side by side. The Comparison sheet has a new block of rows (15 onward) showing the narrow-range results.
A6: Why a narrow-range fit was added
A7: The original full-range SH fit has ~0.27 °C residual RMS because of non-equilibrium data at the cold (points 1–4) and hot (points 18–20) extremes — the bath was ramping, not settled. These outer points dragged the global fit coefficients around even though they won't be visited during operation. Fitting only the 5–40 °C subset (10 points per thermistor) gives coefficients that are specifically tuned to the quiet middle of the calibration, and residuals in the 10–30 °C operating range collapse to ~0.10 °C RMS — close to what your reference probe's 0.1 °C digit can even resolve.
A9: Why B-model and not Steinhart-Hart
A10: The classic curvature that justifies Steinhart-Hart (the "smile" residual pattern) only matters when you fit across a wide temperature span. Over a 35 °C fit window (5–40 °C), the B-model — a straight line of ln R versus 1/T — is effectively indistinguishable from SH. Fewer parameters also means less risk of overfitting, and the two-parameter form is trivial to invert in firmware: T = B / (ln R − intercept) − 273.15. If you later widen the operating range beyond ~40 °C, re-evaluate.
A12: How the fit is calculated (since SLOPE/LINEST wouldn't work)
A13: SLOPE, INTERCEPT, and LINEST refuse ranges that contain non-numeric values, and our in-range mask leaves zeros for ignored rows. So the B-fit is computed by hand via the closed-form least-squares formulas: slope = (n·Σxy − Σx·Σy) / (n·Σxx − (Σx)²) and intercept = (Σy − slope·Σx) / n, where x = 1/T_K, y = ln R, and the sums run over rows where the mask indicator L = 1. R² is computed from the same sums. This is exactly what SLOPE/INTERCEPT do internally; we just made the masking explicit.
A15: How to tune the fit
A16: The four blue input cells (B47–B50) control the two windows. B47–B48 define which points enter the fit (default 5 to 40 °C). B49–B50 define which points are used for the residual statistics (default 10 to 30 °C, your actual operating range). Change either pair and every dependent cell recomputes. Useful sanity checks: tightening the fit window to 10–30 °C gives the purest operating-range fit but fewer degrees of freedom (6 points, 4 DOF); widening to 0–60 °C starts to let the bad tail points back in and inflates residuals.
A18: What to do with the narrow-range coefficients
... A25: Full-range fits: B differs by 15.7 K (0.41 %), R₀ by 631 Ω (0.64 %). Narrow-range fits: B differs by ~4 K (0.1 %), R₀ by ~340 Ω (0.3 %). The pair is more closely matched than the original fits suggested — the extra scatter in the wide-range fits was absorbing non-equilibrium error, not real bead-to-bead variation.

Sheet Thermistor_1
A1: NTC Thermistor Characterization — NTC-01
A3: Thermistor ID: | B3: NTC-01
A4: Reference T₀ (°C): | B4: 25 | C4: T₀ (K): | D4: =B4+273.15 -> 298.15
A6: Measurement Data (fill the blue cells — T_ref is your reference probe, R_meas is multimeter reading)
A7: Point # | B7: T_ref (°C) | C7: T_ref (K) | D7: R_meas (Ω) | E7: 1/T (1/K) | F7: ln(R) | G7: R_fit B-model (Ω) | H7: Residual (%) | I7: (ln R)³ [SH helper] | J7: ln R (SH) | K7: (ln R)³ (SH) | L7: In fit range | M7: In op range | N7: fit-masked 1/T | O7: fit-masked ln R | P7: T_narrow (°C) | Q7: Resid. in op (°C)
A8: 1 | B8: 0.5 | C8: =IF(B8="","",B8+273.15) -> 273.65 | D8: 308000 | E8: =IF(C8="","",1/C8) -> 0.0036543029 | F8: =IF(D8="","",LN(D8)) -> 12.637855 | G8: =IF(OR(D8="",$B$30=""),"",$B$31*EXP($B$30*(E8-1/$D$4))) -> 316028.69 | H8: =IF(OR(D8="",G8=""),"",(G8-D8)/D8*100) -> 2.6067167 | I8: =IF(F8="","",F8^3) -> 2018.4598 | J8: =IF(F8="","",F8) -> 12.637855 | K8: =IF(F8="","",F8^3) -> 2018.4598 | L8: =IF(AND(ISNUMBER(B8),ISNUMBER(D8),B8>=$B$47,B8<=$B$48),1,0) -> 0 | M8: =IF(AND(ISNUMBER(B8),ISNUMBER(D8),B8>=$B$49,B8<=$B$50),1,0) -> 0 | N8: =IF(L8=1, 1/(B8+273.15), 0) -> 0 | O8: =IF(L8=1, LN(D8), 0) -> 0 | P8: =IF(ISNUMBER(D8),$B$53/(LN(D8)-$B$54)-273.15,"") -> 0.90327461 | Q8: =IF(AND(M8=1,ISNUMBER(P8),ISNUMBER(B8)),P8-B8,"")
A9: 2 | B9: 1.7 | C9: =IF(B9="","",B9+273.15) -> 274.85 | D9: 293000 | E9: =IF(C9="","",1/C9) -> 0.0036383482 | F9: =IF(D9="","",LN(D9)) -> 12.587928 | G9: =IF(OR(D9="",$B$30=""),"",$B$31*EXP($B$30*(E9-1/$D$4))) -> 297091.61 | H9: =IF(OR(D9="",G9=""),"",(G9-D9)/D9*100) -> 1.3964533 | I9: =IF(F9="","",F9^3) -> 1994.6318 | J9: =IF(F9="","",F9) -> 12.587928 | K9: =IF(F9="","",F9^3) -> 1994.6318 | L9: =IF(AND(ISNUMBER(B9),ISNUMBER(D9),B9>=$B$47,B9<=$B$48),1,0) -> 0 | M9: =IF(AND(ISNUMBER(B9),ISNUMBER(D9),B9>=$B$49,B9<=$B$50),1,0) -> 0 | N9: =IF(L9=1, 1/(B9+273.15), 0) -> 0 | O9: =IF(L9=1, LN(D9), 0) -> 0 | P9: =IF(ISNUMBER(D9),$B$53/(LN(D9)-$B$54)-273.15,"") -> 1.8893138 | Q9: =IF(AND(M9=1,ISNUMBER(P9),ISNUMBER(B9)),P9-B9,"")
A10: 3 | B10: 4.6 | C10: =IF(B10="","",B10+273.15) -> 277.75 | D10: 250000 | E10: =IF(C10="","",1/C10) -> 0.00360036 | F10: =IF(D10="","",LN(D10)) -> 12.429216 | G10: =IF(OR(D10="",$B$30=""),"",$B$31*EXP($B$30*(E10-1/$D$4))) -> 256444.72 | H10: =IF(OR(D10="",G10=""),"",(G10-D10)/D10*100) -> 2.5778879 | I10: =IF(F10="","",F10^3) -> 1920.1326 | J10: =IF(F10="","",F10) -> 12.429216 | K10: =IF(F10="","",F10^3) -> 1920.1326 | L10: =IF(AND(ISNUMBER(B10),ISNUMBER(D10),B10>=$B$47,B10<=$B$48),1,0) -> 0 | M10: =IF(AND(ISNUMBER(B10),ISNUMBER(D10),B10>=$B$49,B10<=$B$50),1,0) -> 0 | N10: =IF(L10=1, 1/(B10+273.15), 0) -> 0 | O10: =IF(L10=1, LN(D10), 0) -> 0 | P10: =IF(ISNUMBER(D10),$B$53/(LN(D10)-$B$54)-273.15,"") -> 5.0714719 | Q10: =IF(AND(M10=1,ISNUMBER(P10),ISNUMBER(B10)),P10-B10,"")
A11: 4 | B11: 9 | C11: =IF(B11="","",B11+273.15) -> 282.15 | D11: 203000 | E11: =IF(C11="","",1/C11) -> 0.0035442141 | F11: =IF(D11="","",LN(D11)) -> 12.220961 | G11: =IF(OR(D11="",$B$30=""),"",$B$31*EXP($B$30*(E11-1/$D$4))) -> 206326.7 | H11: =IF(OR(D11="",G11=""),"",(G11-D11)/D11*100) -> 1.6387695 | I11: =IF(F11="","",F11^3) -> 1825.2237 | J11: =IF(F11="","",F11) -> 12.220961 | K11: =IF(F11="","",F11^3) -> 1825.2237 | L11: =IF(AND(ISNUMBER(B11),ISNUMBER(D11),B11>=$B$47,B11<=$B$48),1,0) -> 1 | M11: =IF(AND(ISNUMBER(B11),ISNUMBER(D11),B11>=$B$49,B11<=$B$50),1,0) -> 0 | N11: =IF(L11=1, 1/(B11+273.15), 0) -> 0.0035442141 | O11: =IF(L11=1, LN(D11), 0) -> 12.220961 | P11: =IF(ISNUMBER(D11),$B$53/(LN(D11)-$B$54)-273.15,"") -> 9.3603905 | Q11: =IF(AND(M11=1,ISNUMBER(P11),ISNUMBER(B11)),P11-B11,"")
A12: 5 | B12: 11.9 | C12: =IF(B12="","",B12+273.15) -> 285.05 | D12: 181000 | E12: =IF(C12="","",1/C12) -> 0.0035081565 | F12: =IF(D12="","",LN(D12)) -> 12.106252 | G12: =IF(OR(D12="",$B$30=""),"",$B$31*EXP($B$30*(E12-1/$D$4))) -> 179434.53 | H12: =IF(OR(D12="",G12=""),"",(G12-D12)/D12*100) -> -0.86490058 | I12: =IF(F12="","",F12^3) -> 1774.3086 | J12: =IF(F12="","",F12) -> 12.106252 | K12: =IF(F12="","",F12^3) -> 1774.3086 | L12: =IF(AND(ISNUMBER(B12),ISNUMBER(D12),B12>=$B$47,B12<=$B$48),1,0) -> 1 | M12: =IF(AND(ISNUMBER(B12),ISNUMBER(D12),B12>=$B$49,B12<=$B$50),1,0) -> 1 | N12: =IF(L12=1, 1/(B12+273.15), 0) -> 0.0035081565 | O12: =IF(L12=1, LN(D12), 0) -> 12.106252 | P12: =IF(ISNUMBER(D12),$B$53/(LN(D12)-$B$54)-273.15,"") -> 11.779731 | Q12: =IF(AND(M12=1,ISNUMBER(P12),ISNUMBER(B12)),P12-B12,"") -> -0.12026948
A13: 6 | B13: 14.5 | C13: =IF(B13="","",B13+273.15) -> 287.65 | D13: 160000 | E13: =IF(C13="","",1/C13) -> 0.0034764471 | F13: =IF(D13="","",LN(D13)) -> 11.982929 | G13: =IF(OR(D13="",$B$30=""),"",$B$31*EXP($B$30*(E13-1/$D$4))) -> 158697.6 | H13: =IF(OR(D13="",G13=""),"",(G13-D13)/D13*100) -> -0.81399862 | I13: =IF(F13="","",F13^3) -> 1720.6359 | J13: =IF(F13="","",F13) -> 11.982929 | K13: =IF(F13="","",F13^3) -> 1720.6359 | L13: =IF(AND(ISNUMBER(B13),ISNUMBER(D13),B13>=$B$47,B13<=$B$48),1,0) -> 1 | M13: =IF(AND(ISNUMBER(B13),ISNUMBER(D13),B13>=$B$49,B13<=$B$50),1,0) -> 1 | N13: =IF(L13=1, 1/(B13+273.15), 0) -> 0.0034764471 | O13: =IF(L13=1, LN(D13), 0) -> 11.982929 | P13: =IF(ISNUMBER(D13),$B$53/(LN(D13)-$B$54)-273.15,"") -> 14.427406 | Q13: =IF(AND(M13=1,ISNUMBER(P13),ISNUMBER(B13)),P13-B13,"") -> -0.072593772
A14: 7 | B14: 18.4 | C14: =IF(B14="","",B14+273.15) -> 291.55 | D14: 134800 | E14: =IF(C14="","",1/C14) -> 0.0034299434 | F14: =IF(D14="","",LN(D14)) -> 11.811547 | G14: =IF(OR(D14="",$B$30=""),"",$B$31*EXP($B$30*(E14-1/$D$4))) -> 132541.09 | H14: =IF(OR(D14="",G14=""),"",(G14-D14)/D14*100) -> -1.6757513 | I14: =IF(F14="","",F14^3) -> 1647.8603 | J14: =IF(F14="","",F14) -> 11.811547 | K14: =IF(F14="","",F14^3) -> 1647.8603 | L14: =IF(AND(ISNUMBER(B14),ISNUMBER(D14),B14>=$B$47,B14<=$B$48),1,0) -> 1 | M14: =IF(AND(ISNUMBER(B14),ISNUMBER(D14),B14>=$B$49,B14<=$B$50),1,0) -> 1 | N14: =IF(L14=1, 1/(B14+273.15), 0) -> 0.0034299434 | O14: =IF(L14=1, LN(D14), 0) -> 11.811547 | P14: =IF(ISNUMBER(D14),$B$53/(LN(D14)-$B$54)-273.15,"") -> 18.189642 | Q14: =IF(AND(M14=1,ISNUMBER(P14),ISNUMBER(B14)),P14-B14,"") -> -0.21035807
A15: 8 | B15: 21.6 | C15: =IF(B15="","",B15+273.15) -> 294.75 | D15: 116480 | E15: =IF(C15="","",1/C15) -> 0.0033927057 | F15: =IF(D15="","",LN(D15)) -> 11.665475 | G15: =IF(OR(D15="",$B$30=""),"",$B$31*EXP($B$30*(E15-1/$D$4))) -> 114740.34 | H15: =IF(OR(D15="",G15=""),"",(G15-D15)/D15*100) -> -1.4935249 | I15: =IF(F15="","",F15^3) -> 1587.4764 | J15: =IF(F15="","",F15) -> 11.665475 | K15: =IF(F15="","",F15^3) -> 1587.4764 | L15: =IF(AND(ISNUMBER(B15),ISNUMBER(D15),B15>=$B$47,B15<=$B$48),1,0) -> 1 | M15: =IF(AND(ISNUMBER(B15),ISNUMBER(D15),B15>=$B$49,B15<=$B$50),1,0) -> 1 | N15: =IF(L15=1, 1/(B15+273.15), 0) -> 0.0033927057 | O15: =IF(L15=1, LN(D15), 0) -> 11.665475 | P15: =IF(ISNUMBER(D15),$B$53/(LN(D15)-$B$54)-273.15,"") -> 21.474868 | Q15: =IF(AND(M15=1,ISNUMBER(P15),ISNUMBER(B15)),P15-B15,"") -> -0.12513243
A16: 9 | B16: 25.5 | C16: =IF(B16="","",B16+273.15) -> 298.65 | D16: 97540 | E16: =IF(C16="","",1/C16) -> 0.0033484011 | F16: =IF(D16="","",LN(D16)) -> 11.488018 | G16: =IF(OR(D16="",$B$30=""),"",$B$31*EXP($B$30*(E16-1/$D$4))) -> 96648.531 | H16: =IF(OR(D16="",G16=""),"",(G16-D16)/D16*100) -> -0.91395223 | I16: =IF(F16="","",F16^3) -> 1516.126 | J16: =IF(F16="","",F16) -> 11.488018 | K16: =IF(F16="","",F16^3) -> 1516.126 | L16: =IF(AND(ISNUMBER(B16),ISNUMBER(D16),B16>=$B$47,B16<=$B$48),1,0) -> 1 | M16: =IF(AND(ISNUMBER(B16),ISNUMBER(D16),B16>=$B$49,B16<=$B$50),1,0) -> 1 | N16: =IF(L16=1, 1/(B16+273.15), 0) -> 0.0033484011 | O16: =IF(L16=1, LN(D16), 0) -> 11.488018 | P16: =IF(ISNUMBER(D16),$B$53/(LN(D16)-$B$54)-273.15,"") -> 25.567003 | Q16: =IF(AND(M16=1,ISNUMBER(P16),ISNUMBER(B16)),P16-B16,"") -> 0.067002848
A17: 10 | B17: 28.2 | C17: =IF(B17="","",B17+273.15) -> 301.35 | D17: 87400 | E17: =IF(C17="","",1/C17) -> 0.0033184005 | F17: =IF(D17="","",LN(D17)) -> 11.378251 | G17: =IF(OR(D17="",$B$30=""),"",$B$31*EXP($B$30*(E17-1/$D$4))) -> 86046.617 | H17: =IF(OR(D17="",G17=""),"",(G17-D17)/D17*100) -> -1.5484927 | I17: =IF(F17="","",F17^3) -> 1473.0805 | J17: =IF(F17="","",F17) -> 11.378251 | K17: =IF(F17="","",F17^3) -> 1473.0805 | L17: =IF(AND(ISNUMBER(B17),ISNUMBER(D17),B17>=$B$47,B17<=$B$48),1,0) -> 1 | M17: =IF(AND(ISNUMBER(B17),ISNUMBER(D17),B17>=$B$49,B17<=$B$50),1,0) -> 1 | N17: =IF(L17=1, 1/(B17+273.15), 0) -> 0.0033184005 | O17: =IF(L17=1, LN(D17), 0) -> 11.378251 | P17: =IF(ISNUMBER(D17),$B$53/(LN(D17)-$B$54)-273.15,"") -> 28.155618 | Q17: =IF(AND(M17=1,ISNUMBER(P17),ISNUMBER(B17)),P17-B17,"") -> -0.044382256
A18: 11 | B18: 31.2 | C18: =IF(B18="","",B18+273.15) -> 304.35 | D18: 77200 | E18: =IF(C18="","",1/C18) -> 0.0032856908 | F18: =IF(D18="","",LN(D18)) -> 11.254155 | G18: =IF(OR(D18="",$B$30=""),"",$B$31*EXP($B$30*(E18-1/$D$4))) -> 75808.096 | H18: =IF(OR(D18="",G18=""),"",(G18-D18)/D18*100) -> -1.8029841 | I18: =IF(F18="","",F18^3) -> 1425.4062 | J18: =IF(F18="","",F18) -> 11.254155 | K18: =IF(F18="","",F18^3) -> 1425.4062 | L18: =IF(AND(ISNUMBER(B18),ISNUMBER(D18),B18>=$B$47,B18<=$B$48),1,0) -> 1 | M18: =IF(AND(ISNUMBER(B18),ISNUMBER(D18),B18>=$B$49,B18<=$B$50),1,0) -> 0 | N18: =IF(L18=1, 1/(B18+273.15), 0) -> 0.0032856908 | O18: =IF(L18=1, LN(D18), 0) -> 11.254155 | P18: =IF(ISNUMBER(D18),$B$53/(LN(D18)-$B$54)-273.15,"") -> 31.136706 | Q18: =IF(AND(M18=1,ISNUMBER(P18),ISNUMBER(B18)),P18-B18,"")
A19: 12 | B19: 35.4 | C19: =IF(B19="","",B19+273.15) -> 308.55 | D19: 65080 | E19: =IF(C19="","",1/C19) -> 0.0032409658 | F19: =IF(D19="","",LN(D19)) -> 11.083373 | G19: =IF(OR(D19="",$B$30=""),"",$B$31*EXP($B$30*(E19-1/$D$4))) -> 63751.07 | H19: =IF(OR(D19="",G19=""),"",(G19-D19)/D19*100) -> -2.0419941 | I19: =IF(F19="","",F19^3) -> 1361.4942 | J19: =IF(F19="","",F19) -> 11.083373 | K19: =IF(F19="","",F19^3) -> 1361.4942 | L19: =IF(AND(ISNUMBER(B19),ISNUMBER(D19),B19>=$B$47,B19<=$B$48),1,0) -> 1 | M19: =IF(AND(ISNUMBER(B19),ISNUMBER(D19),B19>=$B$49,B19<=$B$50),1,0) -> 0 | N19: =IF(L19=1, 1/(B19+273.15), 0) -> 0.0032409658 | O19: =IF(L19=1, LN(D19), 0) -> 11.083373 | P19: =IF(ISNUMBER(D19),$B$53/(LN(D19)-$B$54)-273.15,"") -> 35.337099 | Q19: =IF(AND(M19=1,ISNUMBER(P19),ISNUMBER(B19)),P19-B19,"")
... A27: 20 | B27: 74 | C27: =IF(B27="","",B27+273.15) -> 347.15 | D27: 15000 | E27: =IF(C27="","",1/C27) -> 0.0028805992 | F27: =IF(D27="","",LN(D27)) -> 9.6158055 | G27: =IF(OR(D27="",$B$30=""),"",$B$31*EXP($B$30*(E27-1/$D$4))) -> 15788.671 | H27: =IF(OR(D27="",G27=""),"",(G27-D27)/D27*100) -> 5.2578085 | I27: =IF(F27="","",F27^3) -> 889.1131 | J27: =IF(F27="","",F27) -> 9.6158055 | K27: =IF(F27="","",F27^3) -> 889.1131 | L27: =IF(AND(ISNUMBER(B27),ISNUMBER(D27),B27>=$B$47,B27<=$B$48),1,0) -> 0 | M27: =IF(AND(ISNUMBER(B27),ISNUMBER(D27),B27>=$B$49,B27<=$B$50),1,0) -> 0 | N27: =IF(L27=1, 1/(B27+273.15), 0) -> 0 | O27: =IF(L27=1, LN(D27), 0) -> 0 | P27: =IF(ISNUMBER(D27),$B$53/(LN(D27)-$B$54)-273.15,"") -> 76.855135 | Q27: =IF(AND(M27=1,ISNUMBER(P27),ISNUMBER(B27)),P27-B27,"")
A29: B-Parameter Model: R(T) = R₀·exp(B·(1/T − 1/T₀)) → plot ln(R) vs 1/T gives slope = B
A30: Slope B (K) | B30: =IFERROR(SLOPE(F8:F27,E8:E27),"") -> 3872.9814
A31: R₀ fitted at T₀ (Ω) | B31: =IFERROR(EXP(INTERCEPT(F8:F27,E8:E27)+B30/D4),"") -> 98773.46
A32: Intercept (ln R₀ − B/T₀) | B32: =IFERROR(INTERCEPT(F8:F27,E8:E27),"") -> -1.489459
A33: R² of ln(R) vs 1/T | B33: =IFERROR(RSQ(F8:F27,E8:E27),"") -> 0.99957188
A34: Points used (N) | B34: =COUNT(D8:D27) -> 20
A35: R @ 25 °C (from fit) (Ω) | B35: =IFERROR(B31*EXP(B30*(1/(25+273.15)-1/D4)),"") -> 98773.46
A36: R @ 0 °C (from fit) (Ω) | B36: =IFERROR(B31*EXP(B30*(1/(0+273.15)-1/D4)),"") -> 324323.05
A37: R @ 50 °C (from fit) (Ω) | B37: =IFERROR(B31*EXP(B30*(1/(50+273.15)-1/D4)),"") -> 36157.136
A39: Steinhart-Hart Model: 1/T = A + B·ln(R) + C·(ln R)³ (LINEST multi-variable regression)
A40: Coefficient A | B40: {=IFERROR(INDEX(LINEST(OFFSET(E8,0,0,COUNT(D8:D27),1),OFFSET(J8,0,0,COUNT(D8:D27),2),TRUE(),FALSE()),1,3),"")} -> 0.00082599698
A41: Coefficient B | B41: {=IFERROR(INDEX(LINEST(OFFSET(E8,0,0,COUNT(D8:D27),1),OFFSET(J8,0,0,COUNT(D8:D27),2),TRUE(),FALSE()),1,2),"")} -> 0.00019874471
A42: Coefficient C | B42: {=IFERROR(INDEX(LINEST(OFFSET(E8,0,0,COUNT(D8:D27),1),OFFSET(J8,0,0,COUNT(D8:D27),2),TRUE(),FALSE()),1,1),"")} -> 1.5682887e-07
A43: T @ R=R₀ (SH, °C) check | B43: =IFERROR(1/(B40+B41*LN(B31)+B42*LN(B31)^3)-273.15,"") -> 25.33691
A45: Narrow-range analysis — fit only the operating-range data (added in v2)
A47: Fit range — T_min (°C): | B47: 5
A48: Fit range — T_max (°C): | B48: 40
A49: Operating range — T_min (°C): | B49: 10
A50: Operating range — T_max (°C): | B50: 30
A52: Narrow-range B-model fit (closed-form least squares on masked rows)
A53: B value (K) | B53: =IFERROR(((SUM(L8:L27)*SUMPRODUCT(N8:N27,O8:O27)-SUM(N8:N27)*SUM(O8:O27))/(SUM(L8:L27)*SUMPRODUCT(N8:N27,N8:N27)-SUM(N8:N27)^2)),"") -> 3816.5643
A54: Intercept (ln R₀ − B/T₀) | B54: =IFERROR(((SUM(O8:O27)-$B$53*SUM(N8:N27))/SUM(L8:L27)),"") -> -1.2885039
...

Sheet Thermistor_2
A1: NTC Thermistor Characterization — NTC-02
A3: Thermistor ID: | B3: NTC-02
A4: Reference T₀ (°C): | B4: 25 | C4: T₀ (K): | D4: =B4+273.15 -> 298.15
A6: Measurement Data (fill the blue cells — T_ref is your reference probe, R_meas is multimeter reading)
A7: Point # | B7: T_ref (°C) | C7: T_ref (K) | D7: R_meas (Ω) | E7: 1/T (1/K) | F7: ln(R) | G7: R_fit B-model (Ω) | H7: Residual (%) | I7: (ln R)³ [SH helper] | J7: ln R (SH) | K7: (ln R)³ (SH) | L7: In fit range | M7: In op range | N7: fit-masked 1/T | O7: fit-masked ln R | P7: T_narrow (°C) | Q7: Resid. in op (°C)
A8: 1 | B8: 0.5 | C8: =IF(B8="","",B8+273.15) -> 273.65 | D8: 312000 | E8: =IF(C8="","",1/C8) -> 0.0036543029 | F8: =IF(D8="","",LN(D8)) -> 12.650758 | G8: =IF(OR(D8="",$B$30=""),"",$B$31*EXP($B$30*(E8-1/$D$4))) -> 312531.29 | H8: =IF(OR(D8="",G8=""),"",(G8-D8)/D8*100) -> 0.17028376 | I8: =IF(F8="","",F8^3) -> 2024.6488 | J8: =IF(F8="","",F8) -> 12.650758 | K8: =IF(F8="","",F8^3) -> 2024.6488 | L8: =IF(AND(ISNUMBER(B8),ISNUMBER(D8),B8>=$B$47,B8<=$B$48),1,0) -> 0 | M8: =IF(AND(ISNUMBER(B8),ISNUMBER(D8),B8>=$B$49,B8<=$B$50),1,0) -> 0 | N8: =IF(L8=1, 1/(B8+273.15), 0) -> 0 | O8: =IF(L8=1, LN(D8), 0) -> 0 | P8: =IF(ISNUMBER(D8),$B$53/(LN(D8)-$B$54)-273.15,"") -> 0.60824285 | Q8: =IF(AND(M8=1,ISNUMBER(P8),ISNUMBER(B8)),P8-B8,"")
A9: 2 | B9: 1.6 | C9: =IF(B9="","",B9+273.15) -> 274.75 | D9: 280000 | E9: =IF(C9="","",1/C9) -> 0.0036396724 | F9: =IF(D9="","",LN(D9)) -> 12.542545 | G9: =IF(OR(D9="",$B$30=""),"",$B$31*EXP($B$30*(E9-1/$D$4))) -> 295382.39 | H9: =IF(OR(D9="",G9=""),"",(G9-D9)/D9*100) -> 5.4937098 | I9: =IF(F9="","",F9^3) -> 1973.1359 | J9: =IF(F9="","",F9) -> 12.542545 | K9: =IF(F9="","",F9^3) -> 1973.1359 | L9: =IF(AND(ISNUMBER(B9),ISNUMBER(D9),B9>=$B$47,B9<=$B$48),1,0) -> 0 | M9: =IF(AND(ISNUMBER(B9),ISNUMBER(D9),B9>=$B$49,B9<=$B$50),1,0) -> 0 | N9: =IF(L9=1, 1/(B9+273.15), 0) -> 0 | O9: =IF(L9=1, LN(D9), 0) -> 0 | P9: =IF(ISNUMBER(D9),$B$53/(LN(D9)-$B$54)-273.15,"") -> 2.7473843 | Q9: =IF(AND(M9=1,ISNUMBER(P9),ISNUMBER(B9)),P9-B9,"")
A10: 3 | B10: 4.9 | C10: =IF(B10="","",B10+273.15) -> 278.05 | D10: 240000 | E10: =IF(C10="","",1/C10) -> 0.0035964755 | F10: =IF(D10="","",LN(D10)) -> 12.388394 | G10: =IF(OR(D10="",$B$30=""),"",$B$31*EXP($B$30*(E10-1/$D$4))) -> 250046.86 | H10: =IF(OR(D10="",G10=""),"",(G10-D10)/D10*100) -> 4.1861937 | I10: =IF(F10="","",F10^3) -> 1901.2755 | J10: =IF(F10="","",F10) -> 12.388394 | K10: =IF(F10="","",F10^3) -> 1901.2755 | L10: =IF(AND(ISNUMBER(B10),ISNUMBER(D10),B10>=$B$47,B10<=$B$48),1,0) -> 0 | M10: =IF(AND(ISNUMBER(B10),ISNUMBER(D10),B10>=$B$49,B10<=$B$50),1,0) -> 0 | N10: =IF(L10=1, 1/(B10+273.15), 0) -> 0 | O10: =IF(L10=1, LN(D10), 0) -> 0 | P10: =IF(ISNUMBER(D10),$B$53/(LN(D10)-$B$54)-273.15,"") -> 5.8529792 | Q10: =IF(AND(M10=1,ISNUMBER(P10),ISNUMBER(B10)),P10-B10,"")
A11: 4 | B11: 9.3 | C11: =IF(B11="","",B11+273.15) -> 282.45 | D11: 200000 | E11: =IF(C11="","",1/C11) -> 0.0035404496 | F11: =IF(D11="","",LN(D11)) -> 12.206073 | G11: =IF(OR(D11="",$B$30=""),"",$B$31*EXP($B$30*(E11-1/$D$4))) -> 201450.09 | H11: =IF(OR(D11="",G11=""),"",(G11-D11)/D11*100) -> 0.72504631 | I11: =IF(F11="","",F11^3) -> 1818.5609 | J11: =IF(F11="","",F11) -> 12.206073 | K11: =IF(F11="","",F11^3) -> 1818.5609 | L11: =IF(AND(ISNUMBER(B11),ISNUMBER(D11),B11>=$B$47,B11<=$B$48),1,0) -> 1 | M11: =IF(AND(ISNUMBER(B11),ISNUMBER(D11),B11>=$B$49,B11<=$B$50),1,0) -> 0 | N11: =IF(L11=1, 1/(B11+273.15), 0) -> 0.0035404496 | O11: =IF(L11=1, LN(D11), 0) -> 12.206073 | P11: =IF(ISNUMBER(D11),$B$53/(LN(D11)-$B$54)-273.15,"") -> 9.6175842 | Q11: =IF(AND(M11=1,ISNUMBER(P11),ISNUMBER(B11)),P11-B11,"")
A12: 5 | B12: 12 | C12: =IF(B12="","",B12+273.15) -> 285.15 | D12: 179400 | E12: =IF(C12="","",1/C12) -> 0.0035069262 | F12: =IF(D12="","",LN(D12)) -> 12.097373 | G12: =IF(OR(D12="",$B$30=""),"",$B$31*EXP($B$30*(E12-1/$D$4))) -> 177014.68 | H12: =IF(OR(D12="",G12=""),"",(G12-D12)/D12*100) -> -1.3296113 | I12: =IF(F12="","",F12^3) -> 1770.4075 | J12: =IF(F12="","",F12) -> 12.097373 | K12: =IF(F12="","",F12^3) -> 1770.4075 | L12: =IF(AND(ISNUMBER(B12),ISNUMBER(D12),B12>=$B$47,B12<=$B$48),1,0) -> 1 | M12: =IF(AND(ISNUMBER(B12),ISNUMBER(D12),B12>=$B$49,B12<=$B$50),1,0) -> 1 | N12: =IF(L12=1, 1/(B12+273.15), 0) -> 0.0035069262 | O12: =IF(L12=1, LN(D12), 0) -> 12.097373 | P12: =IF(ISNUMBER(D12),$B$53/(LN(D12)-$B$54)-273.15,"") -> 11.910759 | Q12: =IF(AND(M12=1,ISNUMBER(P12),ISNUMBER(B12)),P12-B12,"") -> -0.089240802
A13: 6 | B13: 14.6 | C13: =IF(B13="","",B13+273.15) -> 287.75 | D13: 158300 | E13: =IF(C13="","",1/C13) -> 0.0034752389 | F13: =IF(D13="","",LN(D13)) -> 11.972247 | G13: =IF(OR(D13="",$B$30=""),"",$B$31*EXP($B$30*(E13-1/$D$4))) -> 156648.8 | H13: =IF(OR(D13="",G13=""),"",(G13-D13)/D13*100) -> -1.0430828 | I13: =IF(F13="","",F13^3) -> 1716.0385 | J13: =IF(F13="","",F13) -> 11.972247 | K13: =IF(F13="","",F13^3) -> 1716.0385 | L13: =IF(AND(ISNUMBER(B13),ISNUMBER(D13),B13>=$B$47,B13<=$B$48),1,0) -> 1 | M13: =IF(AND(ISNUMBER(B13),ISNUMBER(D13),B13>=$B$49,B13<=$B$50),1,0) -> 1 | N13: =IF(L13=1, 1/(B13+273.15), 0) -> 0.0034752389 | O13: =IF(L13=1, LN(D13), 0) -> 11.972247 | P13: =IF(ISNUMBER(D13),$B$53/(LN(D13)-$B$54)-273.15,"") -> 14.596961 | Q13: =IF(AND(M13=1,ISNUMBER(P13),ISNUMBER(B13)),P13-B13,"") -> -0.0030391243
A14: 7 | B14: 18.4 | C14: =IF(B14="","",B14+273.15) -> 291.55 | D14: 134000 | E14: =IF(C14="","",1/C14) -> 0.0034299434 | F14: =IF(D14="","",LN(D14)) -> 11.805595 | G14: =IF(OR(D14="",$B$30=""),"",$B$31*EXP($B$30*(E14-1/$D$4))) -> 131537.15 | H14: =IF(OR(D14="",G14=""),"",(G14-D14)/D14*100) -> -1.8379468 | I14: =IF(F14="","",F14^3) -> 1645.3703 | J14: =IF(F14="","",F14) -> 11.805595 | K14: =IF(F14="","",F14^3) -> 1645.3703 | L14: =IF(AND(ISNUMBER(B14),ISNUMBER(D14),B14>=$B$47,B14<=$B$48),1,0) -> 1 | M14: =IF(AND(ISNUMBER(B14),ISNUMBER(D14),B14>=$B$49,B14<=$B$50),1,0) -> 1 | N14: =IF(L14=1, 1/(B14+273.15), 0) -> 0.0034299434 | O14: =IF(L14=1, LN(D14), 0) -> 11.805595 | P14: =IF(ISNUMBER(D14),$B$53/(LN(D14)-$B$54)-273.15,"") -> 18.25426 | Q14: =IF(AND(M14=1,ISNUMBER(P14),ISNUMBER(B14)),P14-B14,"") -> -0.14573952
A15: 8 | B15: 21.6 | C15: =IF(B15="","",B15+273.15) -> 294.75 | D15: 116250 | E15: =IF(C15="","",1/C15) -> 0.0033927057 | F15: =IF(D15="","",LN(D15)) -> 11.663498 | G15: =IF(OR(D15="",$B$30=""),"",$B$31*EXP($B$30*(E15-1/$D$4))) -> 113937.88 | H15: =IF(OR(D15="",G15=""),"",(G15-D15)/D15*100) -> -1.9889204 | I15: =IF(F15="","",F15^3) -> 1586.6696 | J15: =IF(F15="","",F15) -> 11.663498 | K15: =IF(F15="","",F15^3) -> 1586.6696 | L15: =IF(AND(ISNUMBER(B15),ISNUMBER(D15),B15>=$B$47,B15<=$B$48),1,0) -> 1 | M15: =IF(AND(ISNUMBER(B15),ISNUMBER(D15),B15>=$B$49,B15<=$B$50),1,0) -> 1 | N15: =IF(L15=1, 1/(B15+273.15), 0) -> 0.0033927057 | O15: =IF(L15=1, LN(D15), 0) -> 11.663498 | P15: =IF(ISNUMBER(D15),$B$53/(LN(D15)-$B$54)-273.15,"") -> 21.44691 | Q15: =IF(AND(M15=1,ISNUMBER(P15),ISNUMBER(B15)),P15-B15,"") -> -0.1530905
A16: 9 | B16: 25.2 | C16: =IF(B16="","",B16+273.15) -> 298.35 | D16: 99000 | E16: =IF(C16="","",1/C16) -> 0.0033517681 | F16: =IF(D16="","",LN(D16)) -> 11.502875 | G16: =IF(OR(D16="",$B$30=""),"",$B$31*EXP($B$30*(E16-1/$D$4))) -> 97294.837 | H16: =IF(OR(D16="",G16=""),"",(G16-D16)/D16*100) -> -1.7223868 | I16: =IF(F16="","",F16^3) -> 1522.016 | J16: =IF(F16="","",F16) -> 11.502875 | K16: =IF(F16="","",F16^3) -> 1522.016 | L16: =IF(AND(ISNUMBER(B16),ISNUMBER(D16),B16>=$B$47,B16<=$B$48),1,0) -> 1 | M16: =IF(AND(ISNUMBER(B16),ISNUMBER(D16),B16>=$B$49,B16<=$B$50),1,0) -> 1 | N16: =IF(L16=1, 1/(B16+273.15), 0) -> 0.0033517681 | O16: =IF(L16=1, LN(D16), 0) -> 11.502875 | P16: =IF(ISNUMBER(D16),$B$53/(LN(D16)-$B$54)-273.15,"") -> 25.141103 | Q16: =IF(AND(M16=1,ISNUMBER(P16),ISNUMBER(B16)),P16-B16,"") -> -0.058896682
A17: 10 | B17: 27.8 | C17: =IF(B17="","",B17+273.15) -> 300.95 | D17: 88600 | E17: =IF(C17="","",1/C17) -> 0.0033228111 | F17: =IF(D17="","",LN(D17)) -> 11.391887 | G17: =IF(OR(D17="",$B$30=""),"",$B$31*EXP($B$30*(E17-1/$D$4))) -> 87012.442 | H17: =IF(OR(D17="",G17=""),"",(G17-D17)/D17*100) -> -1.7918259 | I17: =IF(F17="","",F17^3) -> 1478.3832 | J17: =IF(F17="","",F17) -> 11.391887 | K17: =IF(F17="","",F17^3) -> 1478.3832 | L17: =IF(AND(ISNUMBER(B17),ISNUMBER(D17),B17>=$B$47,B17<=$B$48),1,0) -> 1 | M17: =IF(AND(ISNUMBER(B17),ISNUMBER(D17),B17>=$B$49,B17<=$B$50),1,0) -> 1 | N17: =IF(L17=1, 1/(B17+273.15), 0) -> 0.0033228111 | O17: =IF(L17=1, LN(D17), 0) -> 11.391887 | P17: =IF(ISNUMBER(D17),$B$53/(LN(D17)-$B$54)-273.15,"") -> 27.748331 | Q17: =IF(AND(M17=1,ISNUMBER(P17),ISNUMBER(B17)),P17-B17,"") -> -0.051668705
A18: 11 | B18: 31.6 | C18: =IF(B18="","",B18+273.15) -> 304.75 | D18: 75900 | E18: =IF(C18="","",1/C18) -> 0.0032813782 | F18: =IF(D18="","",LN(D18)) -> 11.237172 | G18: =IF(OR(D18="",$B$30=""),"",$B$31*EXP($B$30*(E18-1/$D$4))) -> 74160.612 | H18: =IF(OR(D18="",G18=""),"",(G18-D18)/D18*100) -> -2.2916835 | I18: =IF(F18="","",F18^3) -> 1418.963 | J18: =IF(F18="","",F18) -> 11.237172 | K18: =IF(F18="","",F18^3) -> 1418.963 | L18: =IF(AND(ISNUMBER(B18),ISNUMBER(D18),B18>=$B$47,B18<=$B$48),1,0) -> 1 | M18: =IF(AND(ISNUMBER(B18),ISNUMBER(D18),B18>=$B$49,B18<=$B$50),1,0) -> 0 | N18: =IF(L18=1, 1/(B18+273.15), 0) -> 0.0032813782 | O18: =IF(L18=1, LN(D18), 0) -> 11.237172 | P18: =IF(ISNUMBER(D18),$B$53/(LN(D18)-$B$54)-273.15,"") -> 31.459745 | Q18: =IF(AND(M18=1,ISNUMBER(P18),ISNUMBER(B18)),P18-B18,"")
A19: 12 | B19: 35.8 | C19: =IF(B19="","",B19+273.15) -> 308.95 | D19: 63550 | E19: =IF(C19="","",1/C19) -> 0.0032367697 | F19: =IF(D19="","",LN(D19)) -> 11.059582 | G19: =IF(OR(D19="",$B$30=""),"",$B$31*EXP($B$30*(E19-1/$D$4))) -> 62437.512 | H19: =IF(OR(D19="",G19=""),"",(G19-D19)/D19*100) -> -1.7505704 | I19: =IF(F19="","",F19^3) -> 1352.7457 | J19: =IF(F19="","",F19) -> 11.059582 | K19: =IF(F19="","",F19^3) -> 1352.7457 | L19: =IF(AND(ISNUMBER(B19),ISNUMBER(D19),B19>=$B$47,B19<=$B$48),1,0) -> 1 | M19: =IF(AND(ISNUMBER(B19),ISNUMBER(D19),B19>=$B$49,B19<=$B$50),1,0) -> 0 | N19: =IF(L19=1, 1/(B19+273.15), 0) -> 0.0032367697 | O19: =IF(L19=1, LN(D19), 0) -> 11.059582 | P19: =IF(ISNUMBER(D19),$B$53/(LN(D19)-$B$54)-273.15,"") -> 35.834372 | Q19: =IF(AND(M19=1,ISNUMBER(P19),ISNUMBER(B19)),P19-B19,"")
... A27: 20 | B27: 78 | C27: =IF(B27="","",B27+273.15) -> 351.15 | D27: 13500 | E27: =IF(C27="","",1/C27) -> 0.0028477858 | F27: =IF(D27="","",LN(D27)) -> 9.510445 | G27: =IF(OR(D27="",$B$30=""),"",$B$31*EXP($B$30*(E27-1/$D$4))) -> 13925.903 | H27: =IF(OR(D27="",G27=""),"",(G27-D27)/D27*100) -> 3.1548335 | I27: =IF(F27="","",F27^3) -> 860.20608 | J27: =IF(F27="","",F27) -> 9.510445 | K27: =IF(F27="","",F27^3) -> 860.20608 | L27: =IF(AND(ISNUMBER(B27),ISNUMBER(D27),B27>=$B$47,B27<=$B$48),1,0) -> 0 | M27: =IF(AND(ISNUMBER(B27),ISNUMBER(D27),B27>=$B$49,B27<=$B$50),1,0) -> 0 | N27: =IF(L27=1, 1/(B27+273.15), 0) -> 0 | O27: =IF(L27=1, LN(D27), 0) -> 0 | P27: =IF(ISNUMBER(D27),$B$53/(LN(D27)-$B$54)-273.15,"") -> 80.08659 | Q27: =IF(AND(M27=1,ISNUMBER(P27),ISNUMBER(B27)),P27-B27,"")
A29: B-Parameter Model: R(T) = R₀·exp(B·(1/T − 1/T₀)) → plot ln(R) vs 1/T gives slope = B
A30: Slope B (K) | B30: =IFERROR(SLOPE(F8:F27,E8:E27),"") -> 3857.2697
A31: R₀ fitted at T₀ (Ω) | B31: =IFERROR(EXP(INTERCEPT(F8:F27,E8:E27)+B30/D4),"") -> 98142.306
A32: Intercept (ln R₀ − B/T₀) | B32: =IFERROR(INTERCEPT(F8:F27,E8:E27),"") -> -1.4431723
A33: R² of ln(R) vs 1/T | B33: =IFERROR(RSQ(F8:F27,E8:E27),"") -> 0.99940055
A34: Points used (N) | B34: =COUNT(D8:D27) -> 20
A35: R @ 25 °C (from fit) (Ω) | B35: =IFERROR(B31*EXP(B30*(1/(25+273.15)-1/D4)),"") -> 98142.306
A36: R @ 0 °C (from fit) (Ω) | B36: =IFERROR(B31*EXP(B30*(1/(0+273.15)-1/D4)),"") -> 320700.15
A37: R @ 50 °C (from fit) (Ω) | B37: =IFERROR(B31*EXP(B30*(1/(50+273.15)-1/D4)),"") -> 36072.859
A39: Steinhart-Hart Model: 1/T = A + B·ln(R) + C·(ln R)³ (LINEST multi-variable regression)
A40: Coefficient A | B40: {=IFERROR(INDEX(LINEST(OFFSET(E8,0,0,COUNT(D8:D27),1),OFFSET(J8,0,0,COUNT(D8:D27),2),TRUE(),FALSE()),1,3),"")} -> 0.0008454763
A41: Coefficient B | B41: {=IFERROR(INDEX(LINEST(OFFSET(E8,0,0,COUNT(D8:D27),1),OFFSET(J8,0,0,COUNT(D8:D27),2),TRUE(),FALSE()),1,2),"")} -> 0.00019538171
A42: Coefficient C | B42: {=IFERROR(INDEX(LINEST(OFFSET(E8,0,0,COUNT(D8:D27),1),OFFSET(J8,0,0,COUNT(D8:D27),2),TRUE(),FALSE()),1,1),"")} -> 1.7029212e-07
A43: T @ R=R₀ (SH, °C) check | B43: =IFERROR(1/(B40+B41*LN(B31)+B42*LN(B31)^3)-273.15,"") -> 25.372861
A45: Narrow-range analysis — fit only the operating-range data (added in v2)
A47: Fit range — T_min (°C): | B47: 5
A48: Fit range — T_max (°C): | B48: 40
A49: Operating range — T_min (°C): | B49: 10
A50: Operating range — T_max (°C): | B50: 30
A52: Narrow-range B-model fit (closed-form least squares on masked rows)
A53: B value (K) | B53: =IFERROR(((SUM(L8:L27)*SUMPRODUCT(N8:N27,O8:O27)-SUM(N8:N27)*SUM(O8:O27))/(SUM(L8:L27)*SUMPRODUCT(N8:N27,N8:N27)-SUM(N8:N27)^2)),"") -> 3820.8243
A54: Intercept (ln R₀ − B/T₀) | B54: =IFERROR(((SUM(O8:O27)-$B$53*SUM(N8:N27))/SUM(L8:L27)),"") -> -1.3061704
...

Sheet Comparison
A1: Summary & Comparison
A3: Parameter | B3: Thermistor 1 | C3: Thermistor 2 | D3: Ratio / Note
A4: ID | B4: =Thermistor_1!B3 -> NTC-01 | C4: =Thermistor_2!B3 -> NTC-02
A5: B value (K) | B5: =Thermistor_1!B30 -> 3872.9814 | C5: =Thermistor_2!B30 -> 3857.2697 | D5: =IFERROR(C5/B5,"") -> 0.99594327
A6: R₀ fitted (Ω) at 25 °C | B6: =Thermistor_1!B31 -> 98773.46 | C6: =Thermistor_2!B31 -> 98142.306 | D6: =IFERROR(C6/B6,"") -> 0.99361008
A7: R² | B7: =Thermistor_1!B33 -> 0.99957188 | C7: =Thermistor_2!B33 -> 0.99940055
A8: R @ 0 °C (Ω) | B8: =Thermistor_1!B36 -> 324323.05 | C8: =Thermistor_2!B36 -> 320700.15 | D8: =IFERROR(C8/B8,"") -> 0.98882935
A9: R @ 50 °C (Ω) | B9: =Thermistor_1!B37 -> 36157.136 | C9: =Thermistor_2!B37 -> 36072.859 | D9: =IFERROR(C9/B9,"") -> 0.99766913
A10: SH Coefficient A | B10: =Thermistor_1!B40 -> 0.00082599698 | C10: =Thermistor_2!B40 -> 0.0008454763
A11: SH Coefficient B | B11: =Thermistor_1!B41 -> 0.00019874471 | C11: =Thermistor_2!B41 -> 0.00019538171
A12: SH Coefficient C | B12: =Thermistor_1!B42 -> 1.5682887e-07 | C12: =Thermistor_2!B42 -> 1.7029212e-07
A13: Points used (N) | B13: =Thermistor_1!B34 -> 20 | C13: =Thermistor_2!B34 -> 20
A15: Narrow-range fit results (v2) — the values you should actually use
A17: Parameter | B17: Thermistor 1 | C17: Thermistor 2 | D17: Ratio / Note
A18: B value (K) — narrow fit | B18: =Thermistor_1!B53 -> 3816.5643 | C18: =Thermistor_2!B53 -> 3820.8243 | D18: =IFERROR(C18/B18,"") -> 1.0011162
A19: Intercept — narrow fit | B19: =Thermistor_1!B54 -> -1.2885039 | C19: =Thermistor_2!B54 -> -1.3061704
A20: R₀ at 25 °C (Ω) — narrow | B20: =Thermistor_1!B55 -> 99939.013 | C20: =Thermistor_2!B55 -> 99601.965 | D20: =IFERROR(C20/B20,"") -> 0.99662746
A21: Points used in fit | B21: =Thermistor_1!B56 -> 10 | C21: =Thermistor_2!B56 -> 10
A22: R² of narrow fit | B22: =Thermistor_1!B57 -> 0.99964904 | C22: =Thermistor_2!B57 -> 0.99970296
A23: Points in op range | B23: =Thermistor_1!B60 -> 6 | C23: =Thermistor_2!B60 -> 6
A24: Residual RMS in op (°C) | B24: =Thermistor_1!B61 -> 0.11979317 | C24: =Thermistor_2!B61 -> 0.098985133
A25: Residual min in op (°C) | B25: =Thermistor_1!B62 -> -0.21035807 | C25: =Thermistor_2!B62 -> -0.1530905
A26: Residual max in op (°C) | B26: =Thermistor_1!B63 -> 0.067002848 | C26: =Thermistor_2!B63 -> -0.0030391243
A27: Residual mean in op (°C) | B27: =Thermistor_1!B64 -> -0.084288862 | C27: =Thermistor_2!B64 -> -0.083612555
